ERROR: 04-08 14:37:09: webpage_download.py:43 : 第 1 次下载 url:http://cup.baidu.com/spider/ 失败, 开始第 2 次尝试
ERROR: 04-08 14:37:09: webpage_download.py:43 : 第 2 次下载 url:http://cup.baidu.com/spider/ 失败, 开始第 3 次尝试
ERROR: 04-08 14:37:09: webpage_download.py:43 : 第 3 次下载 url:http://cup.baidu.com/spider/ 失败, 开始第 4 次尝试
ERROR: 04-08 14:37:09: webpage_download.py:48 : 下载 url:http://cup.baidu.com/spider/ 失败, Traceback (most recent call last):, requests.exceptions.ConnectionError: HTTPConnectionPool(host='cup.baidu.com', port=80): Max retries exceeded with url: /spider/ (Caused by NewConnectionError('<urllib3.connection.HTTPConnection object at 0x7fe3f40859b0>: Failed to establish a new connection: [Errno 111] Connection refused',))
ERROR: 04-08 14:37:37: webpage_download.py:43 : 第 1 次下载 url:https://med.sina.com/health/article_detail_100_1_9284.html 失败, 开始第 2 次尝试
ERROR: 04-08 14:37:38: webpage_download.py:43 : 第 2 次下载 url:https://med.sina.com/health/article_detail_100_1_9284.html 失败, 开始第 3 次尝试
ERROR: 04-08 14:37:38: webpage_download.py:43 : 第 1 次下载 url:https://med.sina.com/health/article_detail_100_1_9285.html 失败, 开始第 2 次尝试
ERROR: 04-08 14:37:39: webpage_download.py:43 : 第 3 次下载 url:https://med.sina.com/health/article_detail_100_1_9284.html 失败, 开始第 4 次尝试
ERROR: 04-08 14:37:39: webpage_download.py:43 : 第 2 次下载 url:https://med.sina.com/health/article_detail_100_1_9285.html 失败, 开始第 3 次尝试
ERROR: 04-08 14:37:40: webpage_download.py:43 : 第 1 次下载 url:https://med.sina.com/health/article_detail_100_1_9299.html 失败, 开始第 2 次尝试
ERROR: 04-08 14:37:40: webpage_download.py:48 : 下载 url:https://med.sina.com/health/article_detail_100_1_9284.html 失败, Traceback (most recent call last):, requests.exceptions.ConnectTimeout: HTTPSConnectionPool(host='med.sina.com', port=443): Max retries exceeded with url: /health/article_detail_100_1_9284.html (Caused by ConnectTimeoutError(<urllib3.connection.HTTPSConnection object at 0x7fe3dc520f60>, 'Connection to med.sina.com timed out. (connect timeout=1)'))
ERROR: 04-08 14:37:40: webpage_download.py:43 : 第 3 次下载 url:https://med.sina.com/health/article_detail_100_1_9285.html 失败, 开始第 4 次尝试
ERROR: 04-08 14:37:40: webpage_download.py:43 : 第 1 次下载 url:https://med.sina.com/health/article_detail_100_1_9283.html 失败, 开始第 2 次尝试
ERROR: 04-08 14:37:41: webpage_download.py:43 : 第 2 次下载 url:https://med.sina.com/health/article_detail_100_1_9299.html 失败, 开始第 3 次尝试
ERROR: 04-08 14:37:41: webpage_download.py:48 : 下载 url:https://med.sina.com/health/article_detail_100_1_9285.html 失败, Traceback (most recent call last):, requests.exceptions.ConnectTimeout: HTTPSConnectionPool(host='med.sina.com', port=443): Max retries exceeded with url: /health/article_detail_100_1_9285.html (Caused by ConnectTimeoutError(<urllib3.connection.HTTPSConnection object at 0x7fe3dcc231d0>, 'Connection to med.sina.com timed out. (connect timeout=1)'))
ERROR: 04-08 14:37:41: webpage_download.py:43 : 第 2 次下载 url:https://med.sina.com/health/article_detail_100_1_9283.html 失败, 开始第 3 次尝试
ERROR: 04-08 14:37:42: webpage_download.py:43 : 第 3 次下载 url:https://med.sina.com/health/article_detail_100_1_9299.html 失败, 开始第 4 次尝试
ERROR: 04-08 14:37:42: webpage_download.py:43 : 第 3 次下载 url:https://med.sina.com/health/article_detail_100_1_9283.html 失败, 开始第 4 次尝试
ERROR: 04-08 14:37:43: webpage_download.py:48 : 下载 url:https://med.sina.com/health/article_detail_100_1_9299.html 失败, Traceback (most recent call last):, requests.exceptions.ConnectTimeout: HTTPSConnectionPool(host='med.sina.com', port=443): Max retries exceeded with url: /health/article_detail_100_1_9299.html (Caused by ConnectTimeoutError(<urllib3.connection.HTTPSConnection object at 0x7fe3d3635470>, 'Connection to med.sina.com timed out. (connect timeout=1)'))
ERROR: 04-08 14:37:43: webpage_download.py:48 : 下载 url:https://med.sina.com/health/article_detail_100_1_9283.html 失败, Traceback (most recent call last):, requests.exceptions.ConnectTimeout: HTTPSConnectionPool(host='med.sina.com', port=443): Max retries exceeded with url: /health/article_detail_100_1_9283.html (Caused by ConnectTimeoutError(<urllib3.connection.HTTPSConnection object at 0x7fe3d1384320>, 'Connection to med.sina.com timed out. (connect timeout=1)'))
ERROR: 04-08 14:37:55: webpage_download.py:43 : 第 1 次下载 url:https://www.sina.com.cn/contactus.html 失败, 开始第 2 次尝试
ERROR: 04-08 17:26:20: webpage_download.py:49 : 第 1 次下载 url:http://cup.baidu.com/spider/ 失败, 开始第 2 次尝试
ERROR: 04-08 17:26:20: webpage_download.py:49 : 第 2 次下载 url:http://cup.baidu.com/spider/ 失败, 开始第 3 次尝试
ERROR: 04-08 17:26:20: webpage_download.py:49 : 第 3 次下载 url:http://cup.baidu.com/spider/ 失败, 开始第 4 次尝试
ERROR: 04-08 17:26:20: webpage_download.py:54 : 下载 url:http://cup.baidu.com/spider/ 失败, Traceback (most recent call last):, requests.exceptions.ConnectionError: HTTPConnectionPool(host='cup.baidu.com', port=80): Max retries exceeded with url: /spider/ (Caused by NewConnectionError('<urllib3.connection.HTTPConnection object at 0x7f7af82322b0>: Failed to establish a new connection: [Errno 111] Connection refused',))
ERROR: 04-08 17:26:49: webpage_download.py:49 : 第 1 次下载 url:https://med.sina.com/health/article_detail_100_1_9285.html 失败, 开始第 2 次尝试
ERROR: 04-08 17:26:49: webpage_download.py:49 : 第 1 次下载 url:https://med.sina.com/health/article_detail_100_1_9284.html 失败, 开始第 2 次尝试
ERROR: 04-08 17:26:50: webpage_download.py:49 : 第 2 次下载 url:https://med.sina.com/health/article_detail_100_1_9285.html 失败, 开始第 3 次尝试
ERROR: 04-08 17:26:50: webpage_download.py:49 : 第 2 次下载 url:https://med.sina.com/health/article_detail_100_1_9284.html 失败, 开始第 3 次尝试
ERROR: 04-08 17:26:50: webpage_download.py:49 : 第 1 次下载 url:https://med.sina.com/health/article_detail_100_1_9299.html 失败, 开始第 2 次尝试
ERROR: 04-08 17:26:51: webpage_download.py:49 : 第 1 次下载 url:https://med.sina.com/health/article_detail_100_1_9283.html 失败, 开始第 2 次尝试
ERROR: 04-08 17:26:51: webpage_download.py:49 : 第 3 次下载 url:https://med.sina.com/health/article_detail_100_1_9284.html 失败, 开始第 4 次尝试
ERROR: 04-08 17:26:51: webpage_download.py:49 : 第 3 次下载 url:https://med.sina.com/health/article_detail_100_1_9285.html 失败, 开始第 4 次尝试
ERROR: 04-08 17:26:51: webpage_download.py:49 : 第 2 次下载 url:https://med.sina.com/health/article_detail_100_1_9299.html 失败, 开始第 3 次尝试
ERROR: 04-08 17:26:52: webpage_download.py:49 : 第 2 次下载 url:https://med.sina.com/health/article_detail_100_1_9283.html 失败, 开始第 3 次尝试
ERROR: 04-08 17:26:52: webpage_download.py:54 : 下载 url:https://med.sina.com/health/article_detail_100_1_9284.html 失败, Traceback (most recent call last):, requests.exceptions.ConnectTimeout: HTTPSConnectionPool(host='med.sina.com', port=443): Max retries exceeded with url: /health/article_detail_100_1_9284.html (Caused by ConnectTimeoutError(<urllib3.connection.HTTPSConnection object at 0x7f7ada031518>, 'Connection to med.sina.com timed out. (connect timeout=1)'))
ERROR: 04-08 17:26:52: webpage_download.py:54 : 下载 url:https://med.sina.com/health/article_detail_100_1_9285.html 失败, Traceback (most recent call last):, requests.exceptions.ConnectTimeout: HTTPSConnectionPool(host='med.sina.com', port=443): Max retries exceeded with url: /health/article_detail_100_1_9285.html (Caused by ConnectTimeoutError(<urllib3.connection.HTTPSConnection object at 0x7f7ada031c88>, 'Connection to med.sina.com timed out. (connect timeout=1)'))
ERROR: 04-08 17:26:52: webpage_download.py:49 : 第 3 次下载 url:https://med.sina.com/health/article_detail_100_1_9299.html 失败, 开始第 4 次尝试
ERROR: 04-08 17:26:53: webpage_download.py:49 : 第 3 次下载 url:https://med.sina.com/health/article_detail_100_1_9283.html 失败, 开始第 4 次尝试
ERROR: 04-08 17:26:54: webpage_download.py:54 : 下载 url:https://med.sina.com/health/article_detail_100_1_9299.html 失败, Traceback (most recent call last):, requests.exceptions.ConnectTimeout: HTTPSConnectionPool(host='med.sina.com', port=443): Max retries exceeded with url: /health/article_detail_100_1_9299.html (Caused by ConnectTimeoutError(<urllib3.connection.HTTPSConnection object at 0x7f7adb2381d0>, 'Connection to med.sina.com timed out. (connect timeout=1)'))
ERROR: 04-08 17:26:54: webpage_download.py:54 : 下载 url:https://med.sina.com/health/article_detail_100_1_9283.html 失败, Traceback (most recent call last):, requests.exceptions.ConnectTimeout: HTTPSConnectionPool(host='med.sina.com', port=443): Max retries exceeded with url: /health/article_detail_100_1_9283.html (Caused by ConnectTimeoutError(<urllib3.connection.HTTPSConnection object at 0x7f7ad9fb6320>, 'Connection to med.sina.com timed out. (connect timeout=1)'))
